2024-05-24 13:07:12,245 - ERROR - Error adding task: [Errno 2] No such file or directory: 'members.txt'
Traceback (most recent call last):
  File "c:\Users\admin\Documents\GitHub\Trellomize\main.py", line 198, in add_members
    with open('members.txt', 'r') as file:
         ^^^^^^^^^^^^^^^^^^^^^^^^
FileNotFoundError: [Errno 2] No such file or directory: 'members.txt'
2024-05-24 13:25:26,504 - ERROR - Error adding task: cannot access local variable 'member_name' where it is not associated with a value
Traceback (most recent call last):
  File "c:\Users\admin\Documents\GitHub\Trellomize\main.py", line 207, in add_members
    log_system_event(f"member '{member_name}' Added successfully")
                                ^^^^^^^^^^^
UnboundLocalError: cannot access local variable 'member_name' where it is not associated with a value
2024-05-24 13:28:12,683 - ERROR - Error adding task: cannot access local variable 'member_name' where it is not associated with a value
Traceback (most recent call last):
  File "c:\Users\admin\Documents\GitHub\Trellomize\main.py", line 208, in add_members
    log_system_event(f"member '{member_name}' Added successfully")
                                ^^^^^^^^^^^
UnboundLocalError: cannot access local variable 'member_name' where it is not associated with a value
2024-05-24 13:41:20,823 - ERROR - Error adding task: cannot access local variable 'member_name' where it is not associated with a value
Traceback (most recent call last):
  File "c:\Users\admin\Documents\GitHub\Trellomize\main.py", line 208, in add_members
    log_system_event(f"member '{member_name}' Added successfully")
                                ^^^^^^^^^^^
UnboundLocalError: cannot access local variable 'member_name' where it is not associated with a value
2024-05-24 13:42:14,009 - ERROR - Error adding task: cannot access local variable 'member_name' where it is not associated with a value
Traceback (most recent call last):
  File "c:\Users\admin\Documents\GitHub\Trellomize\main.py", line 208, in add_members
    log_system_event(f"member '{member_name}' Added successfully")
                                ^^^^^^^^^^^
UnboundLocalError: cannot access local variable 'member_name' where it is not associated with a value
2024-05-24 13:42:58,772 - ERROR - Error adding task: cannot access local variable 'member_name' where it is not associated with a value
Traceback (most recent call last):
  File "c:\Users\admin\Documents\GitHub\Trellomize\main.py", line 208, in add_members
    log_system_event(f"member '{member_name}' Added successfully")
                                ^^^^^^^^^^^
UnboundLocalError: cannot access local variable 'member_name' where it is not associated with a value
2024-05-24 15:24:51,680 - ERROR - Error in add_project function: cannot access local variable 'username' where it is not associated with a value
Traceback (most recent call last):
  File "c:\Users\admin\Documents\GitHub\Trellomize\main.py", line 77, in add_project
    log_user_action(username, project_name)
                    ^^^^^^^^
UnboundLocalError: cannot access local variable 'username' where it is not associated with a value
2024-05-24 15:24:51,683 - ERROR - Error adding task: cannot access local variable 'member_name' where it is not associated with a value
Traceback (most recent call last):
  File "c:\Users\admin\Documents\GitHub\Trellomize\main.py", line 208, in add_members
    log_system_event(f"member '{member_name}' Added successfully")
                                ^^^^^^^^^^^
UnboundLocalError: cannot access local variable 'member_name' where it is not associated with a value
2024-05-24 19:21:44,793 - ERROR - Error adding task: cannot access local variable 'member_name' where it is not associated with a value
Traceback (most recent call last):
  File "c:\Users\admin\Documents\GitHub\Trellomize\main.py", line 209, in add_members
    log_system_event(f"member '{member_name}' Added successfully")
                                ^^^^^^^^^^^
UnboundLocalError: cannot access local variable 'member_name' where it is not associated with a value
2024-05-24 19:21:59,300 - ERROR - Error adding task: cannot access local variable 'member_name' where it is not associated with a value
Traceback (most recent call last):
  File "c:\Users\admin\Documents\GitHub\Trellomize\main.py", line 209, in add_members
    log_system_event(f"member '{member_name}' Added successfully")
                                ^^^^^^^^^^^
UnboundLocalError: cannot access local variable 'member_name' where it is not associated with a value
2024-05-24 19:22:18,774 - ERROR - Error adding task: cannot access local variable 'member_name' where it is not associated with a value
Traceback (most recent call last):
  File "c:\Users\admin\Documents\GitHub\Trellomize\main.py", line 209, in add_members
    log_system_event(f"member '{member_name}' Added successfully")
                                ^^^^^^^^^^^
UnboundLocalError: cannot access local variable 'member_name' where it is not associated with a value
2024-05-26 14:01:28,983 - ERROR - Error in add_project function: 'str' object does not support the context manager protocol
Traceback (most recent call last):
  File "c:\Users\admin\Documents\GitHub\Trellomize\main.py", line 68, in add_project
    with open('projects.txt', 'r') as file:
TypeError: 'str' object does not support the context manager protocol
2024-05-26 14:01:28,990 - ERROR - Error in add_project function: 'str' object does not support the context manager protocol
Traceback (most recent call last):
  File "c:\Users\admin\Documents\GitHub\Trellomize\main.py", line 68, in add_project
    with open('projects.txt', 'r') as file:
TypeError: 'str' object does not support the context manager protocol
2024-05-26 14:01:28,994 - ERROR - Error in add_project function: 'str' object does not support the context manager protocol
Traceback (most recent call last):
  File "c:\Users\admin\Documents\GitHub\Trellomize\main.py", line 68, in add_project
    with open('projects.txt', 'r') as file:
TypeError: 'str' object does not support the context manager protocol
2024-05-26 14:03:40,927 - ERROR - Error in add_project function: 'str' object does not support the context manager protocol
Traceback (most recent call last):
  File "c:\Users\admin\Documents\GitHub\Trellomize\main.py", line 68, in add_project
    with open('projects.txt', 'r') as file:
TypeError: 'str' object does not support the context manager protocol
2024-05-26 14:03:40,934 - ERROR - Error in add_project function: 'str' object does not support the context manager protocol
Traceback (most recent call last):
  File "c:\Users\admin\Documents\GitHub\Trellomize\main.py", line 68, in add_project
    with open('projects.txt', 'r') as file:
TypeError: 'str' object does not support the context manager protocol
2024-05-26 14:03:40,938 - ERROR - Error in add_project function: 'str' object does not support the context manager protocol
Traceback (most recent call last):
  File "c:\Users\admin\Documents\GitHub\Trellomize\main.py", line 68, in add_project
    with open('projects.txt', 'r') as file:
TypeError: 'str' object does not support the context manager protocol
2024-05-26 14:12:20,719 - ERROR - Error in add_project function: 'str' object does not support the context manager protocol
Traceback (most recent call last):
  File "c:\Users\admin\Documents\GitHub\Trellomize\main.py", line 68, in add_project
    with open('projects.txt', 'r') as file:
TypeError: 'str' object does not support the context manager protocol
2024-05-26 14:12:20,724 - ERROR - Error in add_project function: 'str' object does not support the context manager protocol
Traceback (most recent call last):
  File "c:\Users\admin\Documents\GitHub\Trellomize\main.py", line 68, in add_project
    with open('projects.txt', 'r') as file:
TypeError: 'str' object does not support the context manager protocol
2024-05-26 14:12:20,728 - ERROR - Error in add_project function: 'str' object does not support the context manager protocol
Traceback (most recent call last):
  File "c:\Users\admin\Documents\GitHub\Trellomize\main.py", line 68, in add_project
    with open('projects.txt', 'r') as file:
TypeError: 'str' object does not support the context manager protocol
2024-05-26 15:55:27,688 - ERROR - Error adding task: cannot access local variable 'member_name' where it is not associated with a value
Traceback (most recent call last):
  File "c:\Users\admin\Documents\GitHub\Trellomize\main.py", line 246, in add_members
    log_system_event(f"member '{member_name}' Added successfully")
                                ^^^^^^^^^^^
UnboundLocalError: cannot access local variable 'member_name' where it is not associated with a value
2024-05-27 15:00:27,388 - ERROR - Error adding task: cannot access local variable 'member_name' where it is not associated with a value
Traceback (most recent call last):
  File "c:\Users\admin\Documents\GitHub\Trellomize\main.py", line 329, in add_members
    log_system_event(f"member '{member_name}' Added successfully")
                                ^^^^^^^^^^^
UnboundLocalError: cannot access local variable 'member_name' where it is not associated with a value
2024-05-27 15:02:40,921 - ERROR - Error adding task: cannot access local variable 'task_name' where it is not associated with a value
Traceback (most recent call last):
  File "c:\Users\admin\Documents\GitHub\Trellomize\main.py", line 158, in add_task
    log_system_event(task_name)
                     ^^^^^^^^^
UnboundLocalError: cannot access local variable 'task_name' where it is not associated with a value
2024-05-27 15:02:53,108 - ERROR - Error adding task: cannot access local variable 'task_name' where it is not associated with a value
Traceback (most recent call last):
  File "c:\Users\admin\Documents\GitHub\Trellomize\main.py", line 158, in add_task
    log_system_event(task_name)
                     ^^^^^^^^^
UnboundLocalError: cannot access local variable 'task_name' where it is not associated with a value
2024-05-27 15:03:13,094 - ERROR - Error adding task: cannot access local variable 'task_name' where it is not associated with a value
Traceback (most recent call last):
  File "c:\Users\admin\Documents\GitHub\Trellomize\main.py", line 158, in add_task
    log_system_event(task_name)
                     ^^^^^^^^^
UnboundLocalError: cannot access local variable 'task_name' where it is not associated with a value
2024-05-27 15:07:13,568 - ERROR - Error adding task: cannot access local variable 'member_name' where it is not associated with a value
Traceback (most recent call last):
  File "c:\Users\admin\Documents\GitHub\Trellomize\main.py", line 370, in add_member_to_task
    log_system_event(f"member  '{member_name}' Added to task successfully")
                                 ^^^^^^^^^^^
UnboundLocalError: cannot access local variable 'member_name' where it is not associated with a value
2024-05-27 15:08:01,132 - ERROR - Error adding task: cannot access local variable 'member_name' where it is not associated with a value
Traceback (most recent call last):
  File "c:\Users\admin\Documents\GitHub\Trellomize\main.py", line 370, in add_member_to_task
    log_system_event(f"member  '{member_name}' Added to task successfully")
                                 ^^^^^^^^^^^
UnboundLocalError: cannot access local variable 'member_name' where it is not associated with a value
2024-05-27 15:08:38,984 - ERROR - Error adding task: cannot access local variable 'member_name' where it is not associated with a value
Traceback (most recent call last):
  File "c:\Users\admin\Documents\GitHub\Trellomize\main.py", line 370, in add_member_to_task
    log_system_event(f"member  '{member_name}' Added to task successfully")
                                 ^^^^^^^^^^^
UnboundLocalError: cannot access local variable 'member_name' where it is not associated with a value
2024-05-27 15:09:23,447 - ERROR - Error adding task: cannot access local variable 'member_name' where it is not associated with a value
Traceback (most recent call last):
  File "c:\Users\admin\Documents\GitHub\Trellomize\main.py", line 370, in add_member_to_task
    log_system_event(f"member  '{member_name}' Added to task successfully")
                                 ^^^^^^^^^^^
UnboundLocalError: cannot access local variable 'member_name' where it is not associated with a value
2024-05-27 15:14:19,096 - ERROR - Error adding task: cannot access local variable 'member_name' where it is not associated with a value
Traceback (most recent call last):
  File "c:\Users\admin\Documents\GitHub\Trellomize\main.py", line 370, in add_member_to_task
    log_system_event(f"member  '{member_name}' Added to task successfully")
                                 ^^^^^^^^^^^
UnboundLocalError: cannot access local variable 'member_name' where it is not associated with a value
2024-05-27 20:46:15,586 - ERROR - Error in add_project function: 'str' object does not support the context manager protocol
Traceback (most recent call last):
  File "c:\Users\admin\Documents\GitHub\Trellomize\main.py", line 72, in add_project
    with open('projects.txt', 'r') as file:
TypeError: 'str' object does not support the context manager protocol
2024-05-27 20:46:15,593 - ERROR - Error in add_project function: 'str' object does not support the context manager protocol
Traceback (most recent call last):
  File "c:\Users\admin\Documents\GitHub\Trellomize\main.py", line 72, in add_project
    with open('projects.txt', 'r') as file:
TypeError: 'str' object does not support the context manager protocol
2024-05-27 20:46:15,610 - ERROR - Error in add_project function: 'str' object does not support the context manager protocol
Traceback (most recent call last):
  File "c:\Users\admin\Documents\GitHub\Trellomize\main.py", line 72, in add_project
    with open('projects.txt', 'r') as file:
TypeError: 'str' object does not support the context manager protocol
2024-05-27 20:53:45,753 - ERROR - Error in add_project function: 'str' object does not support the context manager protocol
Traceback (most recent call last):
  File "c:\Users\admin\Documents\GitHub\Trellomize\main.py", line 72, in add_project
    with open('projects.txt', 'r') as file:
TypeError: 'str' object does not support the context manager protocol
2024-05-27 20:53:45,758 - ERROR - Error in add_project function: 'str' object does not support the context manager protocol
Traceback (most recent call last):
  File "c:\Users\admin\Documents\GitHub\Trellomize\main.py", line 72, in add_project
    with open('projects.txt', 'r') as file:
TypeError: 'str' object does not support the context manager protocol
2024-05-27 20:53:45,763 - ERROR - Error in add_project function: 'str' object does not support the context manager protocol
Traceback (most recent call last):
  File "c:\Users\admin\Documents\GitHub\Trellomize\main.py", line 72, in add_project
    with open('projects.txt', 'r') as file:
TypeError: 'str' object does not support the context manager protocol
